Workbook

Sheet CSA 덤프 v1.0
A1: Seq. | B1: 기출 | C1: Q 번호 | D1: 아리 | E1: 썸머 | F1: 에릭 | G1: 구분 | H1: 본문 | I1: 비고 | J1: 확인필요 | K1: 검수자 | L1: 검수일자
A2: 1 | B2: 2 | C2: 1 | G2: 문제 | H2: NO.1 Which ServiceNow capability allows you to provide knowledge articles, via a conversational messaging interface?
A3: 2 | B3: =B2 -> 2 | C3: =C2 -> 1 | F3: =F2 -> 0 | G3: 보기 | H3: (A). Agent Assist
A4: 3 | B4: =B3 -> 2 | C4: =C3 -> 1 | F4: =F3 -> 0 | G4: 보기 | H4: (B). Virtual Agent
A5: 4 | B5: =B4 -> 2 | C5: =C4 -> 1 | F5: =F4 -> 0 | G5: 보기 | H5: (C). Now Messenger
A6: 5 | B6: =B5 -> 2 | C6: =C5 -> 1 | F6: =F5 -> 0 | G6: 보기 | H6: (D). Connect Agent
A7: 6 | B7: =B6 -> 2 | C7: =C6 -> 1 | F7: =F6 -> 0 | G7: 답 | H7: B
A8: 7 | B8: =B7 -> 2 | C8: =C7 -> 1 | F8: =F7 -> 0
A9: 8 | B9: 1 | C9: 2 | G9: 문제 | H9: NO.2 What feature do you use to specify which users are able to access a Service Catalog Item?
A10: 9 | B10: =B9 -> 1 | C10: =C9 -> 2 | F10: =F9 -> 0 | G10: 보기 | H10: (A). Can Read Role
A11: 10 | B11: =B10 -> 1 | C11: =C10 -> 2 | F11: =F10 -> 0 | G11: 보기 | H11: (B). Catalog User Role
A12: 11 | B12: =B11 -> 1 | C12: =C11 -> 2 | F12: =F11 -> 0 | G12: 보기 | H12: (C). Can Order Tab
A13: 12 | B13: =B12 -> 1 | C13: =C12 -> 2 | F13: =F12 -> 0 | G13: 보기 | H13: (D). User Criteria
A14: 13 | B14: =B13 -> 1 | C14: =C13 -> 2 | F14: =F13 -> 0 | G14: 답 | H14: D
A15: 14 | B15: =B14 -> 1 | C15: =C14 -> 2 | F15: =F14 -> 0
A16: 15 | B16: 0 | C16: 3 | G16: 문제 | H16: NO.3 How are Workflows moved between instances?
A17: 16 | B17: =B16 -> 0 | C17: =C16 -> 3 | F17: =F16 -> 0 | G17: 보기 | H17: (A). Workflows are moved using Update Sets
A18: 17 | B18: =B17 -> 0 | C18: =C17 -> 3 | F18: =F17 -> 0 | G18: 보기 | H18: (B). Workflows are moved using Transform Maps
A19: 18 | B19: =B18 -> 0 | C19: =C18 -> 3 | F19: =F18 -> 0 | G19: 보기 | H19: (C). Workflows are moved using Application Sets
A20: 19 | B20: =B19 -> 0 | C20: =C19 -> 3 | F20: =F19 -> 0 | G20: 보기 | H20: (D). Workflows cannot be moved between instances
A21: 20 | B21: =B20 -> 0 | C21: =C20 -> 3 | F21: =F20 -> 0 | G21: 답 | H21: A
A22: 21 | B22: =B21 -> 0 | C22: =C21 -> 3 | F22: =F21 -> 0
A23: 22 | B23: 2 | C23: 4 | G23: 문제 | H23: NO.4 Which role can manage multiple knowledge bases?
A24: 23 | B24: =B23 -> 2 | C24: =C23 -> 4 | F24: =F23 -> 0 | G24: 보기 | H24: (A). knowledge_base_admin
A25: 24 | B25: =B24 -> 2 | C25: =C24 -> 4 | F25: =F24 -> 0 | G25: 보기 | H25: (B). kb_admin
A26: 25 | B26: =B25 -> 2 | C26: =C25 -> 4 | F26: =F25 -> 0 | G26: 보기 | H26: (C). sn_kb_admin
A27: 26 | B27: =B26 -> 2 | C27: =C26 -> 4 | F27: =F26 -> 0 | G27: 보기 | H27: (D). knowledge_admin
A28: 27 | B28: =B27 -> 2 | C28: =C27 -> 4 | F28: =F27 -> 0 | G28: 답 | H28: D
A29: 28 | B29: =B28 -> 2 | C29: =C28 -> 4 | F29: =F28 -> 0
A30: 29 | B30: 0 | C30: 5 | G30: 문제 | H30: NO.5 Reports can be created from which different places in the platform? (Choose two.)
A31: 30 | B31: =B30 -> 0 | C31: =C30 -> 5 | F31: =F30 -> 0 | G31: 보기 | H31: (A). List column heading
A32: 31 | B32: =B31 -> 0 | C32: =C31 -> 5 | F32: =F31 -> 0 | G32: 보기 | H32: (B). Metrics module
A33: 32 | B33: =B32 -> 0 | C33: =C32 -> 5 | F33: =F32 -> 0 | G33: 보기 | H33: (C). Statistics module
A34: 33 | B34: =B33 -> 0 | C34: =C33 -> 5 | F34: =F33 -> 0 | G34: 보기 | H34: (D). View / Run module
A35: 34 | B35: =B34 -> 0 | C35: =C34 -> 5 | F35: =F34 -> 0 | G35: 답 | H35: AD
A36: 35 | B36: =B35 -> 0 | C36: =C35 -> 5 | F36: =F35 -> 0
A37: 36 | B37: 0 | C37: 6 | G37: 문제 | H37: NO.6 What refers to an application or system that accesses a remote service or another computer system, known as a server?
A38: 37 | B38: =B37 -> 0 | C38: =C37 -> 6 | F38: =F37 -> 0 | G38: 보기 | H38: (A). Server
A39: 38 | B39: =B38 -> 0 | C39: =C38 -> 6 | F39: =F38 -> 0 | G39: 보기 | H39: (B). Client
A40: 39 | B40: =B39 -> 0 | C40: =C39 -> 6 | F40: =F39 -> 0 | G40: 보기 | H40: (C). Script
...

Sheet 문제풀이
A1: Seq. | B1: 기출 | C1: Q 번호 | D1: 1차 | E1: 2차 | F1: 3차 | G1: 4차 | H1: 구분 | I1: 본문 | J1: ="3차 "&ROUND(COUNTIF(J2:J1795,TRUE)/SUM(COUNTIF(J3:J1795,TRUE),COUNTIF(J3:J1795,FALSE))*100,2)&"%" -> 3차 71.61% | K1: ="3차 "&ROUND(COUNTIF(K2:K1795,TRUE)/SUM(COUNTIF(K3:K1795,TRUE),COUNTIF(K3:K1795,FALSE))*100,2)&"%" -> 3차 72.97% | L1: ="3차 "&ROUND(COUNTIF(L2:L1795,TRUE)/SUM(COUNTIF(L3:L1795,TRUE),COUNTIF(L3:L1795,FALSE))*100,2)&"%" -> 3차 84.21% | M1: ="4차 "&ROUND(COUNTIF(M2:M1795,TRUE)/SUM(COUNTIF(M3:M1795,TRUE),COUNTIF(M3:M1795,FALSE))*100,2)&"%" -> 4차 66.67% | N1: 오답 수
A2: 1 | B2: 2 | C2: 1 | H2: ='CSA 덤프 v1.0'!G2 -> 문제 | I2: ='CSA 덤프 v1.0'!H2 -> NO.1 Which ServiceNow capability allows you to provide knowledge articles, via a conversational messaging interface?
A3: 2 | B3: =B2 -> 2 | C3: =C2 -> 1 | H3: ='CSA 덤프 v1.0'!G3 -> 보기 | I3: ='CSA 덤프 v1.0'!H3 -> (A). Agent Assist
A4: 3 | B4: =B3 -> 2 | C4: =C3 -> 1 | H4: ='CSA 덤프 v1.0'!G4 -> 보기 | I4: ='CSA 덤프 v1.0'!H4 -> (B). Virtual Agent
A5: 4 | B5: =B4 -> 2 | C5: =C4 -> 1 | H5: ='CSA 덤프 v1.0'!G5 -> 보기 | I5: ='CSA 덤프 v1.0'!H5 -> (C). Now Messenger
A6: 5 | B6: =B5 -> 2 | C6: =C5 -> 1 | H6: ='CSA 덤프 v1.0'!G6 -> 보기 | I6: ='CSA 덤프 v1.0'!H6 -> (D). Connect Agent
A7: 6 | B7: =B6 -> 2 | C7: =C6 -> 1 | D7: b | H7: ='CSA 덤프 v1.0'!G7 -> 답 | I7: b | J7: =IF(ISBLANK(D7),"",D7=$I7) -> TRUE | K7: =IF(ISBLANK(E7),"",E7=$I7) | L7: =IF(ISBLANK(F7),"",F7=$I7) | M7: =IF(ISBLANK(G7),"",G7=$I7) | N7: =COUNTIF(J7:M7,FALSE) -> 0
A8: 7 | B8: =B7 -> 2 | C8: =C7 -> 1 | H8: ='CSA 덤프 v1.0'!G8 -> 0 | I8: ='CSA 덤프 v1.0'!H8 -> 0
A9: 8 | B9: 1 | C9: 2 | H9: ='CSA 덤프 v1.0'!G9 -> 문제 | I9: ='CSA 덤프 v1.0'!H9 -> NO.2 What feature do you use to specify which users are able to access a Service Catalog Item?
A10: 9 | B10: =B9 -> 1 | C10: =C9 -> 2 | H10: ='CSA 덤프 v1.0'!G10 -> 보기 | I10: ='CSA 덤프 v1.0'!H10 -> (A). Can Read Role
A11: 10 | B11: =B10 -> 1 | C11: =C10 -> 2 | H11: ='CSA 덤프 v1.0'!G11 -> 보기 | I11: ='CSA 덤프 v1.0'!H11 -> (B). Catalog User Role
A12: 11 | B12: =B11 -> 1 | C12: =C11 -> 2 | H12: ='CSA 덤프 v1.0'!G12 -> 보기 | I12: ='CSA 덤프 v1.0'!H12 -> (C). Can Order Tab
A13: 12 | B13: =B12 -> 1 | C13: =C12 -> 2 | H13: ='CSA 덤프 v1.0'!G13 -> 보기 | I13: ='CSA 덤프 v1.0'!H13 -> (D). User Criteria
A14: 13 | B14: =B13 -> 1 | C14: =C13 -> 2 | D14: d | H14: ='CSA 덤프 v1.0'!G14 -> 답 | I14: ='CSA 덤프 v1.0'!H14 -> D | J14: =IF(ISBLANK(D14),"",D14=$I14) -> TRUE | K14: =IF(ISBLANK(E14),"",E14=$I14) | L14: =IF(ISBLANK(F14),"",F14=$I14) | M14: =IF(ISBLANK(G14),"",G14=$I14) | N14: =COUNTIF(J14:M14,FALSE) -> 0
A15: 14 | B15: =B14 -> 1 | C15: =C14 -> 2 | H15: ='CSA 덤프 v1.0'!G15 -> 0 | I15: ='CSA 덤프 v1.0'!H15 -> 0
A16: 15 | B16: 0 | C16: 3 | H16: ='CSA 덤프 v1.0'!G16 -> 문제 | I16: ='CSA 덤프 v1.0'!H16 -> NO.3 How are Workflows moved between instances?
A17: 16 | B17: =B16 -> 0 | C17: =C16 -> 3 | H17: ='CSA 덤프 v1.0'!G17 -> 보기 | I17: ='CSA 덤프 v1.0'!H17 -> (A). Workflows are moved using Update Sets
A18: 17 | B18: =B17 -> 0 | C18: =C17 -> 3 | H18: ='CSA 덤프 v1.0'!G18 -> 보기 | I18: ='CSA 덤프 v1.0'!H18 -> (B). Workflows are moved using Transform Maps
A19: 18 | B19: =B18 -> 0 | C19: =C18 -> 3 | H19: ='CSA 덤프 v1.0'!G19 -> 보기 | I19: ='CSA 덤프 v1.0'!H19 -> (C). Workflows are moved using Application Sets
A20: 19 | B20: =B19 -> 0 | C20: =C19 -> 3 | H20: ='CSA 덤프 v1.0'!G20 -> 보기 | I20: ='CSA 덤프 v1.0'!H20 -> (D). Workflows cannot be moved between instances
A21: 20 | B21: =B20 -> 0 | C21: =C20 -> 3 | D21: a | H21: ='CSA 덤프 v1.0'!G21 -> 답 | I21: ='CSA 덤프 v1.0'!H21 -> A | J21: =IF(ISBLANK(D21),"",D21=$I21) -> TRUE | K21: =IF(ISBLANK(E21),"",E21=$I21) | L21: =IF(ISBLANK(F21),"",F21=$I21) | M21: =IF(ISBLANK(G21),"",G21=$I21) | N21: =COUNTIF(J21:M21,FALSE) -> 0
A22: 21 | B22: =B21 -> 0 | C22: =C21 -> 3 | H22: ='CSA 덤프 v1.0'!G22 -> 0 | I22: ='CSA 덤프 v1.0'!H22 -> 0
A23: 22 | B23: 2 | C23: 4 | H23: ='CSA 덤프 v1.0'!G23 -> 문제 | I23: ='CSA 덤프 v1.0'!H23 -> NO.4 Which role can manage multiple knowledge bases?
A24: 23 | B24: =B23 -> 2 | C24: =C23 -> 4 | H24: ='CSA 덤프 v1.0'!G24 -> 보기 | I24: ='CSA 덤프 v1.0'!H24 -> (A). knowledge_base_admin
A25: 24 | B25: =B24 -> 2 | C25: =C24 -> 4 | H25: ='CSA 덤프 v1.0'!G25 -> 보기 | I25: ='CSA 덤프 v1.0'!H25 -> (B). kb_admin
A26: 25 | B26: =B25 -> 2 | C26: =C25 -> 4 | H26: ='CSA 덤프 v1.0'!G26 -> 보기 | I26: ='CSA 덤프 v1.0'!H26 -> (C). sn_kb_admin
A27: 26 | B27: =B26 -> 2 | C27: =C26 -> 4 | H27: ='CSA 덤프 v1.0'!G27 -> 보기 | I27: ='CSA 덤프 v1.0'!H27 -> (D). knowledge_admin
A28: 27 | B28: =B27 -> 2 | C28: =C27 -> 4 | D28: d | H28: ='CSA 덤프 v1.0'!G28 -> 답 | I28: ='CSA 덤프 v1.0'!H28 -> D | J28: =IF(ISBLANK(D28),"",D28=$I28) -> TRUE | K28: =IF(ISBLANK(E28),"",E28=$I28) | L28: =IF(ISBLANK(F28),"",F28=$I28) | M28: =IF(ISBLANK(G28),"",G28=$I28) | N28: =COUNTIF(J28:M28,FALSE) -> 0
A29: 28 | B29: =B28 -> 2 | C29: =C28 -> 4 | H29: ='CSA 덤프 v1.0'!G29 -> 0 | I29: ='CSA 덤프 v1.0'!H29 -> 0
A30: 29 | B30: 0 | C30: 5 | H30: ='CSA 덤프 v1.0'!G30 -> 문제 | I30: ='CSA 덤프 v1.0'!H30 -> NO.5 Reports can be created from which different places in the platform? (Choose two.)
A31: 30 | B31: =B30 -> 0 | C31: =C30 -> 5 | H31: ='CSA 덤프 v1.0'!G31 -> 보기 | I31: ='CSA 덤프 v1.0'!H31 -> (A). List column heading
A32: 31 | B32: =B31 -> 0 | C32: =C31 -> 5 | H32: ='CSA 덤프 v1.0'!G32 -> 보기 | I32: ='CSA 덤프 v1.0'!H32 -> (B). Metrics module
A33: 32 | B33: =B32 -> 0 | C33: =C32 -> 5 | H33: ='CSA 덤프 v1.0'!G33 -> 보기 | I33: ='CSA 덤프 v1.0'!H33 -> (C). Statistics module
A34: 33 | B34: =B33 -> 0 | C34: =C33 -> 5 | H34: ='CSA 덤프 v1.0'!G34 -> 보기 | I34: ='CSA 덤프 v1.0'!H34 -> (D). View / Run module
A35: 34 | B35: =B34 -> 0 | C35: =C34 -> 5 | D35: ad | H35: ='CSA 덤프 v1.0'!G35 -> 답 | I35: ='CSA 덤프 v1.0'!H35 -> AD | J35: =IF(ISBLANK(D35),"",D35=$I35) -> TRUE | K35: =IF(ISBLANK(E35),"",E35=$I35) | L35: =IF(ISBLANK(F35),"",F35=$I35) | M35: =IF(ISBLANK(G35),"",G35=$I35) | N35: =COUNTIF(J35:M35,FALSE) -> 0
A36: 35 | B36: =B35 -> 0 | C36: =C35 -> 5 | H36: ='CSA 덤프 v1.0'!G36 -> 0 | I36: ='CSA 덤프 v1.0'!H36 -> 0
A37: 36 | B37: 0 | C37: 6 | H37: ='CSA 덤프 v1.0'!G37 -> 문제 | I37: ='CSA 덤프 v1.0'!H37 -> NO.6 What refers to an application or system that accesses a remote service or another computer system, known as a server?
A38: 37 | B38: =B37 -> 0 | C38: =C37 -> 6 | H38: ='CSA 덤프 v1.0'!G38 -> 보기 | I38: ='CSA 덤프 v1.0'!H38 -> (A). Server
A39: 38 | B39: =B38 -> 0 | C39: =C38 -> 6 | H39: ='CSA 덤프 v1.0'!G39 -> 보기 | I39: ='CSA 덤프 v1.0'!H39 -> (B). Client
A40: 39 | B40: =B39 -> 0 | C40: =C39 -> 6 | H40: ='CSA 덤프 v1.0'!G40 -> 보기 | I40: ='CSA 덤프 v1.0'!H40 -> (C). Script
...

Sheet 그 외 기출내용
A1: Field란 무엇인가
A2: 설명 주고 정답 Catalog Builder이였던듯?
A3: Knowledge Article 모두 볼 수 있게 하는거 All View Setting 어쩌고
A4: Knowledge Article 권한 설정 Team, Department, Group
A5: 유저 정보 바꾸려면 뭐 눌러야하냐 Gear, Magnifier
A6: UI Policy 뭐 있냐(3개) View links, View Buttons, View 어쩌고 등
A7: 업데이트 했을때 notification가게 하려면 administrator가 뭐 해야하냐
A8: High Security Setting하려면 뭐해야하냐 ? Elevate Role 함
A9: table 관계 설명주고 Base table이랑 parent child 구분
A10: Group 정의, Role 정의
A11: Core 테이블과 Parent 테이블 비교
A12: https://quizlet.com/662858700/csa-2022-flash-cards/
